import asyncio

import functools

from .main import TaskSyncManager
from . import main
from ..task.functions import make_task_with_task_type
from ..task.task import *
from .task import TaskManager
from ..logger import Logger


async def register_task_to_master(context, master_addr, result_receiver_address, task_type, job, callback, exp_id):
    Logger().log("* register_task_to_master")
    conn = main.MasterConnection(context, master_addr)

    conn.connect()
    await conn.dispatch_msg_coro('task_register_req', {
        'result_receiver_address': result_receiver_address.to_dict(),
        'task_type': task_type.to_str(),
        'task': job.to_dict()
    })

    header, body = await conn.recv_msg()
    TaskSyncManager().unpend_experiment(exp_id)

    if header != 'task_register_res':
        callback_args = dict()
        callback_args['status'] = 'error'
        callback_args['body'] = 'dist-task Internal Error'

        asyncio.get_event_loop().call_soon_threadsafe(functools.partial(callback, **callback_args))
        raise Exception('Task Register Fail')

    status = body['status']
    task_token = TaskToken.from_bytes(body['task_token'])

    if status == 'success':
        await conn.dispatch_msg_coro('task_register_ack', {})
        task = make_task_with_task_type(task_type, job.to_dict(), 'master', task_token, result_receiver_address)
        task.callback = callback
        task.exp_id = exp_id

        TaskManager().add_task(task)

        if TaskSyncManager().check_cancel_exp(exp_id):
            TaskSyncManager().remove_from_cancel_queue(exp_id)
            cancel_task_to_master(context, master_addr, task)
    elif status == 'fail':
        error_code = body['error_code']

        callback_args = dict()
        callback_args['status'] = 'error'
        callback_args['body'] = error_code

        asyncio.get_event_loop().call_soon_threadsafe(functools.partial(callback, **callback_args))

        raise Exception('Task Register Fail')
    else:
        # invalid message
        callback_args = dict()
        callback_args['status'] = 'error'
        callback_args['body'] = 'dist-task Internal Error'

        asyncio.get_event_loop().call_soon_threadsafe(functools.partial(callback, **callback_args))
        raise Exception('Task Register Fail')

    conn.close()


async def cancel_task_to_master(context, master_addr, task):
    conn = main.MasterConnection(context, master_addr)
    conn.connect()
    await conn.dispatch_msg_coro('task_cancel_req', {
        'task_token': task.task_token.to_bytes()
    })

    callback_args = dict()
    callback = task.callback

    # TODO: [SB] Why is task deleted here?
    TaskManager().del_task(task)
    header, body = await conn.recv_msg()
    # nothing to do using response message.
    conn.close()

    callback_args['status'] = 'cancel'
    callback_args['body'] = None
    asyncio.get_event_loop().call_soon_threadsafe(functools.partial(callback, **callback_args))
